Workbook

Sheet Customers
A1: Date | B1: Customer Name | C1: Shipping Address | D1: Phone Number | E1: Email Address
A2: 46172 | B2: Julia | C2: N/A, Mueang Chiang Mai, Chiang Mai, 50000, Thailand | D2: 66998877 | E2: julia@gmail.com
A3: 46172 | B3: Leo | C3: N/A, N/A, N/A, 3000, USA | D3: 66998878 | E3: leo@gmail.com
A4: 46172 | B4: Trevor | C4: N/A, Los Santos, N/A, N/A, USA | D4: 66998879 | E4: trevor@gta.com
A5: 46172 | B5: Mike | C5: N/A, Los Santos, N/A, 40000, USA | D5: +188888 | E5: mike@gmail.com
A6: 46172 | B6: Mary | C6: N/A, Mueang, Chiang Mai, 50000, Thailand | D6: +6699999 | E6: mary@gmail.com
A7: 46172 | B7: Avril | C7: N/A, New York, NY, N/A, USA | D7: 66998882 | E7: avril@vistas.com
A8: 46171 | B8: Justin Bieber | C8: 100 Bay St, Toronto, ON, M5J 2N8, Canada | D8: 66998883 | E8: jbieber@music.com
A9: 46170 | B9: AvrilLwin | C9: Huay Kaew Road, Mueang Chiang Mai, Chiang Mai, 50300, Thailand | D9: 66998884 | E9: lwin@vistas.com
A10: 46170 | B10: Franklin | C10: N/A, N/A, N/A, N/A, USA | D10: 66998885 | E10: franklin@gta.com
A11: 46170 | B11: Jeneffer | C11: N/A, N/A, N/A, N/A, USA | D11: 66998886 | E11: jeneffer@gmail.com
A12: 46170 | B12: Michael Decenta | C12: N/A, Los Santos, N/A, N/A, USA | D12: 66998887 | E12: michael@decenta.com
A13: 46175 | B13: Haily | C13: N/A, N/A, N/A, 4000, USA | D13: 66998888 | E13: None

Sheet Inventory
A1: Product ID | B1: Product Name | C1: Category | D1: Price (USD/THB) | E1: Color Variant | F1: Current Stock | G1: Units Sold | H1: Original Stock | I1: Status
A2: PROD-011 | B2: Cozy Oversized Hoodie | C2: Apparel | D2: $50 / 1,700 THB | E2: Black | F2: =IF(E2="", IF(A2="", "", SUM(OFFSET(F2, -4, 0, 4, 1))), H2-G2) | G2: =IF(E2="", IF(A2="", "", SUM(OFFSET(G2, -4, 0, 4, 1))), SUMIFS('Daily Sales'!$G:$G, 'Daily Sales'!$B:$B, A2, 'Daily Sales'!$K:$K, E2)) | H2: 50
A3: PROD-011 | B3: Cozy Oversized Hoodie | C3: Apparel | D3: $50 / 1,700 THB | E3: Red | F3: =IF(E3="", IF(A3="", "", SUM(OFFSET(F3, -4, 0, 4, 1))), H3-G3) | G3: =IF(E3="", IF(A3="", "", SUM(OFFSET(G3, -4, 0, 4, 1))), SUMIFS('Daily Sales'!$G:$G, 'Daily Sales'!$B:$B, A3, 'Daily Sales'!$K:$K, E3)) | H3: 50
A4: PROD-011 | B4: Cozy Oversized Hoodie | C4: Apparel | D4: $50 / 1,700 THB | E4: Green | F4: =IF(E4="", IF(A4="", "", SUM(OFFSET(F4, -4, 0, 4, 1))), H4-G4) | G4: =IF(E4="", IF(A4="", "", SUM(OFFSET(G4, -4, 0, 4, 1))), SUMIFS('Daily Sales'!$G:$G, 'Daily Sales'!$B:$B, A4, 'Daily Sales'!$K:$K, E4)) | H4: 50
A5: PROD-011 | B5: Cozy Oversized Hoodie | C5: Apparel | D5: $50 / 1,700 THB | E5: Dark Blue | F5: =IF(E5="", IF(A5="", "", SUM(OFFSET(F5, -4, 0, 4, 1))), H5-G5) | G5: =IF(E5="", IF(A5="", "", SUM(OFFSET(G5, -4, 0, 4, 1))), SUMIFS('Daily Sales'!$G:$G, 'Daily Sales'!$B:$B, A5, 'Daily Sales'!$K:$K, E5)) | H5: 50
A6: PROD-011 Total | F6: =IF(E6="", IF(A6="", "", SUM(OFFSET(F6, -4, 0, 4, 1))), H6-G6) | G6: =IF(E6="", IF(A6="", "", SUM(OFFSET(G6, -4, 0, 4, 1))), SUMIFS('Daily Sales'!$G:$G, 'Daily Sales'!$B:$B, A6, 'Daily Sales'!$K:$K, E6)) | H6: =SUM(H2:H5) | I6: ⚠️ Low Stock
A7: PROD-007 | B7: Racing Edition Polo Shirt | C7: Apparel | D7: $45 / 1,550 THB | E7: Black | F7: =IF(E7="", IF(A7="", "", SUM(OFFSET(F7, -4, 0, 4, 1))), H7-G7) | G7: =IF(E7="", IF(A7="", "", SUM(OFFSET(G7, -4, 0, 4, 1))), SUMIFS('Daily Sales'!$G:$G, 'Daily Sales'!$B:$B, A7, 'Daily Sales'!$K:$K, E7)) | H7: 50
A8: PROD-007 | B8: Racing Edition Polo Shirt | C8: Apparel | D8: $45 / 1,550 THB | E8: Red | F8: =IF(E8="", IF(A8="", "", SUM(OFFSET(F8, -4, 0, 4, 1))), H8-G8) | G8: =IF(E8="", IF(A8="", "", SUM(OFFSET(G8, -4, 0, 4, 1))), SUMIFS('Daily Sales'!$G:$G, 'Daily Sales'!$B:$B, A8, 'Daily Sales'!$K:$K, E8)) | H8: 50
A9: PROD-007 | B9: Racing Edition Polo Shirt | C9: Apparel | D9: $45 / 1,550 THB | E9: Green | F9: =IF(E9="", IF(A9="", "", SUM(OFFSET(F9, -4, 0, 4, 1))), H9-G9) | G9: =IF(E9="", IF(A9="", "", SUM(OFFSET(G9, -4, 0, 4, 1))), SUMIFS('Daily Sales'!$G:$G, 'Daily Sales'!$B:$B, A9, 'Daily Sales'!$K:$K, E9)) | H9: 50
A10: PROD-007 | B10: Racing Edition Polo Shirt | C10: Apparel | D10: $45 / 1,550 THB | E10: Dark Blue | F10: =IF(E10="", IF(A10="", "", SUM(OFFSET(F10, -4, 0, 4, 1))), H10-G10) | G10: =IF(E10="", IF(A10="", "", SUM(OFFSET(G10, -4, 0, 4, 1))), SUMIFS('Daily Sales'!$G:$G, 'Daily Sales'!$B:$B, A10, 'Daily Sales'!$K:$K, E10)) | H10: 50
A11: PROD-007 Total | F11: =IF(E11="", IF(A11="", "", SUM(OFFSET(F11, -4, 0, 4, 1))), H11-G11) | G11: =IF(E11="", IF(A11="", "", SUM(OFFSET(G11, -4, 0, 4, 1))), SUMIFS('Daily Sales'!$G:$G, 'Daily Sales'!$B:$B, A11, 'Daily Sales'!$K:$K, E11)) | H11: =SUM(H7:H10) | I11: 🟢 Healthy
A12: PROD-010 | B12: Premium Minimalist Tee | C12: Apparel | D12: $25 / 850 THB | E12: Black | F12: =IF(E12="", IF(A12="", "", SUM(OFFSET(F12, -4, 0, 4, 1))), H12-G12) | G12: =IF(E12="", IF(A12="", "", SUM(OFFSET(G12, -4, 0, 4, 1))), SUMIFS('Daily Sales'!$G:$G, 'Daily Sales'!$B:$B, A12, 'Daily Sales'!$K:$K, E12)) | H12: 50
A13: PROD-010 | B13: Premium Minimalist Tee | C13: Apparel | D13: $25 / 850 THB | E13: Red | F13: =IF(E13="", IF(A13="", "", SUM(OFFSET(F13, -4, 0, 4, 1))), H13-G13) | G13: =IF(E13="", IF(A13="", "", SUM(OFFSET(G13, -4, 0, 4, 1))), SUMIFS('Daily Sales'!$G:$G, 'Daily Sales'!$B:$B, A13, 'Daily Sales'!$K:$K, E13)) | H13: 50
A14: PROD-010 | B14: Premium Minimalist Tee | C14: Apparel | D14: $25 / 850 THB | E14: Green | F14: =IF(E14="", IF(A14="", "", SUM(OFFSET(F14, -4, 0, 4, 1))), H14-G14) | G14: =IF(E14="", IF(A14="", "", SUM(OFFSET(G14, -4, 0, 4, 1))), SUMIFS('Daily Sales'!$G:$G, 'Daily Sales'!$B:$B, A14, 'Daily Sales'!$K:$K, E14)) | H14: 50
A15: PROD-010 | B15: Premium Minimalist Tee | C15: Apparel | D15: $25 / 850 THB | E15: Dark Blue | F15: =IF(E15="", IF(A15="", "", SUM(OFFSET(F15, -4, 0, 4, 1))), H15-G15) | G15: =IF(E15="", IF(A15="", "", SUM(OFFSET(G15, -4, 0, 4, 1))), SUMIFS('Daily Sales'!$G:$G, 'Daily Sales'!$B:$B, A15, 'Daily Sales'!$K:$K, E15)) | H15: 50
A16: PROD-010 Total | F16: =IF(E16="", IF(A16="", "", SUM(OFFSET(F16, -4, 0, 4, 1))), H16-G16) | G16: =IF(E16="", IF(A16="", "", SUM(OFFSET(G16, -4, 0, 4, 1))), SUMIFS('Daily Sales'!$G:$G, 'Daily Sales'!$B:$B, A16, 'Daily Sales'!$K:$K, E16)) | H16: =SUM(H12:H15) | I16: 🟢 Healthy
A17: PROD-006 | B17: Active Dry-Fit T-Shirt | C17: Apparel | D17: $30 / 1,000 THB | E17: Black | F17: =IF(E17="", IF(A17="", "", SUM(OFFSET(F17, -4, 0, 4, 1))), H17-G17) | G17: =IF(E17="", IF(A17="", "", SUM(OFFSET(G17, -4, 0, 4, 1))), SUMIFS('Daily Sales'!$G:$G, 'Daily Sales'!$B:$B, A17, 'Daily Sales'!$K:$K, E17)) | H17: 50
A18: PROD-006 | B18: Active Dry-Fit T-Shirt | C18: Apparel | D18: $30 / 1,000 THB | E18: Red | F18: =IF(E18="", IF(A18="", "", SUM(OFFSET(F18, -4, 0, 4, 1))), H18-G18) | G18: =IF(E18="", IF(A18="", "", SUM(OFFSET(G18, -4, 0, 4, 1))), SUMIFS('Daily Sales'!$G:$G, 'Daily Sales'!$B:$B, A18, 'Daily Sales'!$K:$K, E18)) | H18: 50
A19: PROD-006 | B19: Active Dry-Fit T-Shirt | C19: Apparel | D19: $30 / 1,000 THB | E19: Green | F19: =IF(E19="", IF(A19="", "", SUM(OFFSET(F19, -4, 0, 4, 1))), H19-G19) | G19: =IF(E19="", IF(A19="", "", SUM(OFFSET(G19, -4, 0, 4, 1))), SUMIFS('Daily Sales'!$G:$G, 'Daily Sales'!$B:$B, A19, 'Daily Sales'!$K:$K, E19)) | H19: 50
A20: PROD-006 | B20: Active Dry-Fit T-Shirt | C20: Apparel | D20: $30 / 1,000 THB | E20: Dark Blue | F20: =IF(E20="", IF(A20="", "", SUM(OFFSET(F20, -4, 0, 4, 1))), H20-G20) | G20: =IF(E20="", IF(A20="", "", SUM(OFFSET(G20, -4, 0, 4, 1))), SUMIFS('Daily Sales'!$G:$G, 'Daily Sales'!$B:$B, A20, 'Daily Sales'!$K:$K, E20)) | H20: 50
A21: PROD-006 Total | F21: =IF(E21="", IF(A21="", "", SUM(OFFSET(F21, -4, 0, 4, 1))), H21-G21) | G21: =IF(E21="", IF(A21="", "", SUM(OFFSET(G21, -4, 0, 4, 1))), SUMIFS('Daily Sales'!$G:$G, 'Daily Sales'!$B:$B, A21, 'Daily Sales'!$K:$K, E21)) | H21: =SUM(H17:H20) | I21: 🟢 Healthy
A22: PROD-005 | B22: Classic Flare Skirt | C22: Apparel | D22: $28 / 950 THB | E22: Black | F22: =IF(E22="", IF(A22="", "", SUM(OFFSET(F22, -4, 0, 4, 1))), H22-G22) | G22: =IF(E22="", IF(A22="", "", SUM(OFFSET(G22, -4, 0, 4, 1))), SUMIFS('Daily Sales'!$G:$G, 'Daily Sales'!$B:$B, A22, 'Daily Sales'!$K:$K, E22)) | H22: 50
A23: PROD-005 | B23: Classic Flare Skirt | C23: Apparel | D23: $28 / 950 THB | E23: Red | F23: =IF(E23="", IF(A23="", "", SUM(OFFSET(F23, -4, 0, 4, 1))), H23-G23) | G23: =IF(E23="", IF(A23="", "", SUM(OFFSET(G23, -4, 0, 4, 1))), SUMIFS('Daily Sales'!$G:$G, 'Daily Sales'!$B:$B, A23, 'Daily Sales'!$K:$K, E23)) | H23: 50
A24: PROD-005 | B24: Classic Flare Skirt | C24: Apparel | D24: $28 / 950 THB | E24: Green | F24: =IF(E24="", IF(A24="", "", SUM(OFFSET(F24, -4, 0, 4, 1))), H24-G24) | G24: =IF(E24="", IF(A24="", "", SUM(OFFSET(G24, -4, 0, 4, 1))), SUMIFS('Daily Sales'!$G:$G, 'Daily Sales'!$B:$B, A24, 'Daily Sales'!$K:$K, E24)) | H24: 50
A25: PROD-005 | B25: Classic Flare Skirt | C25: Apparel | D25: $28 / 950 THB | E25: Dark Blue | F25: =IF(E25="", IF(A25="", "", SUM(OFFSET(F25, -4, 0, 4, 1))), H25-G25) | G25: =IF(E25="", IF(A25="", "", SUM(OFFSET(G25, -4, 0, 4, 1))), SUMIFS('Daily Sales'!$G:$G, 'Daily Sales'!$B:$B, A25, 'Daily Sales'!$K:$K, E25)) | H25: 50
A26: PROD-005 Total | F26: =IF(E26="", IF(A26="", "", SUM(OFFSET(F26, -4, 0, 4, 1))), H26-G26) | G26: =IF(E26="", IF(A26="", "", SUM(OFFSET(G26, -4, 0, 4, 1))), SUMIFS('Daily Sales'!$G:$G, 'Daily Sales'!$B:$B, A26, 'Daily Sales'!$K:$K, E26)) | H26: =SUM(H22:H25) | I26: 🟢 Healthy
A27: PROD-008 | B27: Classic Camp Collar Shirt | C27: Apparel | D27: $40 / 1,350 THB | E27: Black | F27: =IF(E27="", IF(A27="", "", SUM(OFFSET(F27, -4, 0, 4, 1))), H27-G27) | G27: =IF(E27="", IF(A27="", "", SUM(OFFSET(G27, -4, 0, 4, 1))), SUMIFS('Daily Sales'!$G:$G, 'Daily Sales'!$B:$B, A27, 'Daily Sales'!$K:$K, E27)) | H27: 50
A28: PROD-008 | B28: Classic Camp Collar Shirt | C28: Apparel | D28: $40 / 1,350 THB | E28: Red | F28: =IF(E28="", IF(A28="", "", SUM(OFFSET(F28, -4, 0, 4, 1))), H28-G28) | G28: =IF(E28="", IF(A28="", "", SUM(OFFSET(G28, -4, 0, 4, 1))), SUMIFS('Daily Sales'!$G:$G, 'Daily Sales'!$B:$B, A28, 'Daily Sales'!$K:$K, E28)) | H28: 50
A29: PROD-008 | B29: Classic Camp Collar Shirt | C29: Apparel | D29: $40 / 1,350 THB | E29: Green | F29: =IF(E29="", IF(A29="", "", SUM(OFFSET(F29, -4, 0, 4, 1))), H29-G29) | G29: =IF(E29="", IF(A29="", "", SUM(OFFSET(G29, -4, 0, 4, 1))), SUMIFS('Daily Sales'!$G:$G, 'Daily Sales'!$B:$B, A29, 'Daily Sales'!$K:$K, E29)) | H29: 50
A30: PROD-008 | B30: Classic Camp Collar Shirt | C30: Apparel | D30: $40 / 1,350 THB | E30: Dark Blue | F30: =IF(E30="", IF(A30="", "", SUM(OFFSET(F30, -4, 0, 4, 1))), H30-G30) | G30: =IF(E30="", IF(A30="", "", SUM(OFFSET(G30, -4, 0, 4, 1))), SUMIFS('Daily Sales'!$G:$G, 'Daily Sales'!$B:$B, A30, 'Daily Sales'!$K:$K, E30)) | H30: 50
A31: PROD-008 Total | F31: =IF(E31="", IF(A31="", "", SUM(OFFSET(F31, -4, 0, 4, 1))), H31-G31) | G31: =IF(E31="", IF(A31="", "", SUM(OFFSET(G31, -4, 0, 4, 1))), SUMIFS('Daily Sales'!$G:$G, 'Daily Sales'!$B:$B, A31, 'Daily Sales'!$K:$K, E31)) | H31: =SUM(H27:H30) | I31: 🟢 Healthy
A32: PROD-009 | B32: Streetwear Cargo Joggers | C32: Apparel | D32: $42 / 1,450 THB | E32: Black | F32: =IF(E32="", IF(A32="", "", SUM(OFFSET(F32, -4, 0, 4, 1))), H32-G32) | G32: =IF(E32="", IF(A32="", "", SUM(OFFSET(G32, -4, 0, 4, 1))), SUMIFS('Daily Sales'!$G:$G, 'Daily Sales'!$B:$B, A32, 'Daily Sales'!$K:$K, E32)) | H32: 50
A33: PROD-009 | B33: Streetwear Cargo Joggers | C33: Apparel | D33: $42 / 1,450 THB | E33: Red | F33: =IF(E33="", IF(A33="", "", SUM(OFFSET(F33, -4, 0, 4, 1))), H33-G33) | G33: =IF(E33="", IF(A33="", "", SUM(OFFSET(G33, -4, 0, 4, 1))), SUMIFS('Daily Sales'!$G:$G, 'Daily Sales'!$B:$B, A33, 'Daily Sales'!$K:$K, E33)) | H33: 50
A34: PROD-009 | B34: Streetwear Cargo Joggers | C34: Apparel | D34: $42 / 1,450 THB | E34: Green | F34: =IF(E34="", IF(A34="", "", SUM(OFFSET(F34, -4, 0, 4, 1))), H34-G34) | G34: =IF(E34="", IF(A34="", "", SUM(OFFSET(G34, -4, 0, 4, 1))), SUMIFS('Daily Sales'!$G:$G, 'Daily Sales'!$B:$B, A34, 'Daily Sales'!$K:$K, E34)) | H34: 50
A35: PROD-009 | B35: Streetwear Cargo Joggers | C35: Apparel | D35: $42 / 1,450 THB | E35: Dark Blue | F35: =IF(E35="", IF(A35="", "", SUM(OFFSET(F35, -4, 0, 4, 1))), H35-G35) | G35: =IF(E35="", IF(A35="", "", SUM(OFFSET(G35, -4, 0, 4, 1))), SUMIFS('Daily Sales'!$G:$G, 'Daily Sales'!$B:$B, A35, 'Daily Sales'!$K:$K, E35)) | H35: 50
A36: PROD-009 Total | F36: =IF(E36="", IF(A36="", "", SUM(OFFSET(F36, -4, 0, 4, 1))), H36-G36) | G36: =IF(E36="", IF(A36="", "", SUM(OFFSET(G36, -4, 0, 4, 1))), SUMIFS('Daily Sales'!$G:$G, 'Daily Sales'!$B:$B, A36, 'Daily Sales'!$K:$K, E36)) | H36: =SUM(H32:H35) | I36: 🟢 Healthy
A37: PROD-002 | B37: AeroFit Sports T-Shirt | C37: Apparel | D37: $35 / 1,200 THB | E37: Black | F37: =IF(E37="", IF(A37="", "", SUM(OFFSET(F37, -4, 0, 4, 1))), H37-G37) | G37: =IF(E37="", IF(A37="", "", SUM(OFFSET(G37, -4, 0, 4, 1))), SUMIFS('Daily Sales'!$G:$G, 'Daily Sales'!$B:$B, A37, 'Daily Sales'!$K:$K, E37)) | H37: 50
A38: PROD-002 | B38: AeroFit Sports T-Shirt | C38: Apparel | D38: $35 / 1,200 THB | E38: Red | F38: =IF(E38="", IF(A38="", "", SUM(OFFSET(F38, -4, 0, 4, 1))), H38-G38) | G38: =IF(E38="", IF(A38="", "", SUM(OFFSET(G38, -4, 0, 4, 1))), SUMIFS('Daily Sales'!$G:$G, 'Daily Sales'!$B:$B, A38, 'Daily Sales'!$K:$K, E38)) | H38: 50
A39: PROD-002 | B39: AeroFit Sports T-Shirt | C39: Apparel | D39: $35 / 1,200 THB | E39: Green | F39: =IF(E39="", IF(A39="", "", SUM(OFFSET(F39, -4, 0, 4, 1))), H39-G39) | G39: =IF(E39="", IF(A39="", "", SUM(OFFSET(G39, -4, 0, 4, 1))), SUMIFS('Daily Sales'!$G:$G, 'Daily Sales'!$B:$B, A39, 'Daily Sales'!$K:$K, E39)) | H39: 50
A40: PROD-002 | B40: AeroFit Sports T-Shirt | C40: Apparel | D40: $35 / 1,200 THB | E40: Dark Blue | F40: =IF(E40="", IF(A40="", "", SUM(OFFSET(F40, -4, 0, 4, 1))), H40-G40) | G40: =IF(E40="", IF(A40="", "", SUM(OFFSET(G40, -4, 0, 4, 1))), SUMIFS('Daily Sales'!$G:$G, 'Daily Sales'!$B:$B, A40, 'Daily Sales'!$K:$K, E40)) | H40: 50
...

Sheet Daily Sales
A1: Date | B1: Product ID | C1: Product Name | D1: Customer | E1: Category | F1: Price (USD/THB) | G1: Units Sold | H1: Original Stock | I1: Current Stock | J1: Status | K1: Color Sold | L1: Size | M1: Revenue (USD)
A2: 46172 | B2: PROD-008 | C2: Classic Camp Collar Shirt | D2: Julia | E2: Apparel | F2: $40 / 1,350 THB | G2: 1 | H2: 50 | I2: =H2 - SUMIFS(G$2:G$28, B$2:B$28, B2, K$2:K$28, K2) | J2: 🟢 Healthy | K2: Black | L2: Large | M2: 40
A3: 46172 | B3: PROD-011 | C3: Cozy Oversized Hoodie | D3: Julia | E3: Apparel | F3: $50 / 1,700 THB | G3: 9 | H3: 50 | I3: =H3 - SUMIFS(G$2:G$28, B$2:B$28, B3, K$2:K$28, K3) | J3: ⚠️ Low Stock | K3: Black | L3: Medium | M3: 450
A4: 46172 | B4: PROD-010 | C4: Premium Minimalist Tee | D4: Leo | E4: Apparel | F4: $25 / 850 THB | G4: 5 | H4: 50 | I4: =H4 - SUMIFS(G$2:G$28, B$2:B$28, B4, K$2:K$28, K4) | J4: 🟢 Healthy | K4: Black | L4: Medium | M4: 125
A5: 46172 | B5: PROD-007 | C5: Racing Edition Polo Shirt | D5: Leo | E5: Apparel | F5: $45 / 1,550 THB | G5: 5 | H5: 50 | I5: =H5 - SUMIFS(G$2:G$28, B$2:B$28, B5, K$2:K$28, K5) | J5: 🟢 Healthy | K5: Dark Blue | L5: Medium | M5: 225
A6: 46172 | B6: PROD-007 | C6: Racing Edition Polo Shirt | D6: Julia | E6: Apparel | F6: $45 / 1,550 THB | G6: 1 | H6: 50 | I6: =H6 - SUMIFS(G$2:G$28, B$2:B$28, B6, K$2:K$28, K6) | J6: 🟢 Healthy | K6: Green | L6: Small | M6: 45
A7: 46172 | B7: PROD-006 | C7: Active Dry-Fit T-Shirt | D7: Julia | E7: Apparel | F7: $30 / 1,000 THB | G7: 1 | H7: 50 | I7: =H7 - SUMIFS(G$2:G$28, B$2:B$28, B7, K$2:K$28, K7) | J7: 🟢 Healthy | K7: Green | L7: Small | M7: 30
A8: 46172 | B8: PROD-009 | C8: Streetwear Cargo Joggers | D8: Julia | E8: Apparel | F8: $42 / 1,450 THB | G8: 1 | H8: 50 | I8: =H8 - SUMIFS(G$2:G$28, B$2:B$28, B8, K$2:K$28, K8) | J8: 🟢 Healthy | K8: Green | L8: Small | M8: 42
A9: 46172 | B9: PROD-010 | C9: Premium Minimalist Tee | D9: Julia | E9: Apparel | F9: $25 / 850 THB | G9: 1 | H9: 50 | I9: =H9 - SUMIFS(G$2:G$28, B$2:B$28, B9, K$2:K$28, K9) | J9: 🟢 Healthy | K9: Green | L9: Small | M9: 25
A10: 46172 | B10: PROD-011 | C10: Cozy Oversized Hoodie | D10: Julia | E10: Apparel | F10: $50 / 1,700 THB | G10: 1 | H10: 50 | I10: =H10 - SUMIFS(G$2:G$28, B$2:B$28, B10, K$2:K$28, K10) | J10: ⚠️ Low Stock | K10: Green | L10: Small | M10: 50
A11: 46172 | B11: PROD-006 | C11: Active Dry-Fit T-Shirt | D11: Julia | E11: Apparel | F11: $30 / 1,000 THB | G11: 5 | H11: 50 | I11: =H11 - SUMIFS(G$2:G$28, B$2:B$28, B11, K$2:K$28, K11) | J11: 🟢 Healthy | K11: Green | L11: Medium | M11: 150
A12: 46172 | B12: PROD-008 | C12: Classic Camp Collar Shirt | D12: Julia | E12: Apparel | F12: $40 / 1,350 THB | G12: 3 | H12: 50 | I12: =H12 - SUMIFS(G$2:G$28, B$2:B$28, B12, K$2:K$28, K12) | J12: 🟢 Healthy | K12: Dark Blue | L12: Large | M12: 120
A13: 46172 | B13: PROD-011 | C13: Cozy Oversized Hoodie | D13: Julia | E13: Apparel | F13: $50 / 1,700 THB | G13: 1 | H13: 50 | I13: =H13 - SUMIFS(G$2:G$28, B$2:B$28, B13, K$2:K$28, K13) | J13: ⚠️ Low Stock | K13: Red | L13: Medium | M13: 50
... A28: 46170 | B28: PROD-002 | C28: AeroFit Sports T-Shirt | D28: Jeneffer | E28: Apparel | F28: $35 / 1,200 THB | G28: 2 | H28: 50 | I28: =H28 - SUMIFS(G$2:G$28, B$2:B$28, B28, K$2:K$28, K28) | J28: ⚠️ Low Stock | K28: Black | L28: Medium | M28: 70
A29: 46175 | B29: PROD-009 | C29: Streetwear Cargo Joggers | D29: Haily | E29: Apparel | F29: $42 / 1,450 THB | G29: 5 | H29: 50 | I29: =H29-SUMIFS(G$2:G$29, B$2:B$29, B29, K$2:K$29, K29) | J29: 🟢 Healthy | K29: Dark Blue | L29: Large | M29: 210

Sheet Sales Pivot Table
B2: The Vistas Studio — Sales Performance Pivot Table
B3: Aggregated daily units sold and gross revenue by product variants.
B5: Product Name | C5: Color Sold | D5: Total Units Sold | E5: Total Revenue (USD)
B6: Active Dry-Fit T-Shirt | C6: Black | D6: 1 | E6: 30
C7: Green | D7: 6 | E7: 180
B8: AeroFit Sports T-Shirt | C8: Black | D8: 2 | E8: 70
B9: Classic Camp Collar Shirt | C9: Black | D9: 1 | E9: 40
C10: Dark Blue | D10: 3 | E10: 120
B11: Classic Flare Skirt | C11: Black | D11: 3 | E11: 84
C12: Dark Blue | D12: 3 | E12: 84
B13: Cozy Oversized Hoodie | C13: Black | D13: 14 | E13: 700
C14: Green | D14: 1 | E14: 50
C15: Red | D15: 2 | E15: 100
B16: Premium Minimalist Tee | C16: Black | D16: 7 | E16: 175
C17: Green | D17: 1 | E17: 25
C18: Red | D18: 1 | E18: 25
B19: Racing Edition Polo Shirt | C19: Black | D19: 2 | E19: 90
C20: Dark Blue | D20: 5 | E20: 225
C21: Green | D21: 1 | E21: 45
C22: Red | D22: 2 | E22: 90
B23: Streetwear Cargo Joggers | C23: Black | D23: 2 | E23: 84
C24: Dark Blue | D24: 5 | E24: 210
C25: Green | D25: 1 | E25: 42
B26: Grand Total | D26: 63 | E26: 2469
